<?xml version="1.0" ?>
<!-- =================================================================================== -->
<!-- |    This document was autogenerated by xacro from /data/QRC2025/ros2/dummy_ws/src/dummy-ros2_description/urdf/dummy-ros2.xacro | -->
<!-- |    EDITING THIS FILE BY HAND IS NOT RECOMMENDED                                 | -->
<!-- =================================================================================== -->
<robot name="dummy">
  <material name="silver">
    <color rgba="0.700 0.700 0.700 1.000"/>
  </material>
  <transmission name="Joint1_tran">
    <type>transmission_interface/SimpleTransmission</type>
    <joint name="Joint1">
      <hardwareInterface>hardware_interface/EffortJointInterface</hardwareInterface>
    </joint>
    <actuator name="Joint1_actr">
      <hardwareInterface>hardware_interface/EffortJointInterface</hardwareInterface>
      <mechanicalReduction>1</mechanicalReduction>
    </actuator>
  </transmission>
  <transmission name="Joint2_tran">
    <type>transmission_interface/SimpleTransmission</type>
    <joint name="Joint2">
      <hardwareInterface>hardware_interface/EffortJointInterface</hardwareInterface>
    </joint>
    <actuator name="Joint2_actr">
      <hardwareInterface>hardware_interface/EffortJointInterface</hardwareInterface>
      <mechanicalReduction>1</mechanicalReduction>
    </actuator>
  </transmission>
  <transmission name="Joint3_tran">
    <type>transmission_interface/SimpleTransmission</type>
    <joint name="Joint3">
      <hardwareInterface>hardware_interface/EffortJointInterface</hardwareInterface>
    </joint>
    <actuator name="Joint3_actr">
      <hardwareInterface>hardware_interface/EffortJointInterface</hardwareInterface>
      <mechanicalReduction>1</mechanicalReduction>
    </actuator>
  </transmission>
  <transmission name="Joint4_tran">
    <type>transmission_interface/SimpleTransmission</type>
    <joint name="Joint4">
      <hardwareInterface>hardware_interface/EffortJointInterface</hardwareInterface>
    </joint>
    <actuator name="Joint4_actr">
      <hardwareInterface>hardware_interface/EffortJointInterface</hardwareInterface>
      <mechanicalReduction>1</mechanicalReduction>
    </actuator>
  </transmission>
  <transmission name="Joint5_tran">
    <type>transmission_interface/SimpleTransmission</type>
    <joint name="Joint5">
      <hardwareInterface>hardware_interface/EffortJointInterface</hardwareInterface>
    </joint>
    <actuator name="Joint5_actr">
      <hardwareInterface>hardware_interface/EffortJointInterface</hardwareInterface>
      <mechanicalReduction>1</mechanicalReduction>
    </actuator>
  </transmission>
  <transmission name="Joint6_tran">
    <type>transmission_interface/SimpleTransmission</type>
    <joint name="Joint6">
      <hardwareInterface>hardware_interface/EffortJointInterface</hardwareInterface>
    </joint>
    <actuator name="Joint6_actr">
      <hardwareInterface>hardware_interface/EffortJointInterface</hardwareInterface>
      <mechanicalReduction>1</mechanicalReduction>
    </actuator>
  </transmission>
  <gazebo>
    <plugin filename="libgazebo_ros_control.so" name="control"/>
  </gazebo>
  <gazebo reference="base_link">
    <material>Gazebo/Silver</material>
    <mu1>0.2</mu1>
    <mu2>0.2</mu2>
    <self_collide>true</self_collide>
    <gravity>true</gravity>
  </gazebo>
  <gazebo reference="link1_1_1">
    <material>Gazebo/Silver</material>
    <mu1>0.2</mu1>
    <mu2>0.2</mu2>
    <self_collide>true</self_collide>
  </gazebo>
  <gazebo reference="link2_1_1">
    <material>Gazebo/Silver</material>
    <mu1>0.2</mu1>
    <mu2>0.2</mu2>
    <self_collide>true</self_collide>
  </gazebo>
  <gazebo reference="link3_1_1">
    <material>Gazebo/Silver</material>
    <mu1>0.2</mu1>
    <mu2>0.2</mu2>
    <self_collide>true</self_collide>
  </gazebo>
  <gazebo reference="link4_1_1">
    <material>Gazebo/Silver</material>
    <mu1>0.2</mu1>
    <mu2>0.2</mu2>
    <self_collide>true</self_collide>
  </gazebo>
  <gazebo reference="link5_1_1">
    <material>Gazebo/Silver</material>
    <mu1>0.2</mu1>
    <mu2>0.2</mu2>
    <self_collide>true</self_collide>
  </gazebo>
  <gazebo reference="link6_1_1">
    <material>Gazebo/Silver</material>
    <mu1>0.2</mu1>
    <mu2>0.2</mu2>
    <self_collide>true</self_collide>
  </gazebo>
  <link name="world"/>
  <joint name="world_joint" type="fixed">
    <parent link="world"/>
    <child link="base_link"/>
    <origin rpy="3.1415926536 3.1415926536 0.0" xyz="0.0 0.0 0.0"/>
  </joint>
  <link name="base_link">
    <inertial>
      <origin rpy="0 0 0" xyz="-0.019286443307707055 0.0005817485706867557 0.05546290448958129"/>
      <mass value="3.4054232030550327"/>
      <inertia ixx="0.006318" ixy="-1.1e-05" ixz="-2e-06" iyy="0.00644" iyz="-0.000164" izz="0.006723"/>
    </inertial>
    <visual>
      <origin rpy="0 0 0" xyz="0 0 0"/>
      <geometry>
        <mesh filename="./meshes/base_link.stl" scale="0.001 0.001 0.001"/>
      </geometry>
      <material name="silver"/>
    </visual>
    <collision>
      <origin rpy="0 0 0" xyz="0 0 0"/>
      <geometry>
        <mesh filename="./meshes/base_link.stl" scale="0.001 0.001 0.001"/>
      </geometry>
    </collision>
  </link>
  <link name="link1_1_1">
    <inertial>
      <origin rpy="0 0 0" xyz="-0.005744742318232344 0.005464327027038366 0.012045619429015192"/>
      <mass value="0.4000119946706078"/>
      <inertia ixx="0.000172" ixy="5.8e-05" ixz="2.7e-05" iyy="0.000152" iyz="-3.9e-05" izz="0.00025"/>
    </inertial>
    <visual>
      <origin rpy="0 0 0" xyz="0.019225 0.000523 -0.100684"/>
      <geometry>
        <mesh filename="./meshes/link1_1_1.stl" scale="0.001 0.001 0.001"/>
      </geometry>
      <material name="silver"/>
    </visual>
    <collision>
      <origin rpy="0 0 0" xyz="0.019225 0.000523 -0.100684"/>
      <geometry>
        <mesh filename="./meshes/link1_1_1.stl" scale="0.001 0.001 0.001"/>
      </geometry>
    </collision>
  </link>
  <link name="link2_1_1">
    <inertial>
      <origin rpy="0 0 0" xyz="0.022476329402049397 0.0015836740439541114 0.0701478637986927"/>
      <mass value="0.9644194016592866"/>
      <inertia ixx="0.003808" ixy="-1e-05" ixz="0.000274" iyy="0.003848" iyz="1.3e-05" izz="0.000499"/>
    </inertial>
    <visual>
      <origin rpy="0 0 0" xyz="0.034725 -0.034477 -0.129184"/>
      <geometry>
        <mesh filename="./meshes/link2_1_1.stl" scale="0.001 0.001 0.001"/>
      </geometry>
      <material name="silver"/>
    </visual>
    <collision>
      <origin rpy="0 0 0" xyz="0.034725 -0.034477 -0.129184"/>
      <geometry>
        <mesh filename="./meshes/link2_1_1.stl" scale="0.001 0.001 0.001"/>
      </geometry>
    </collision>
  </link>
  <link name="link3_1_1">
    <inertial>
      <origin rpy="0 0 0" xyz="-0.010730263185093621 -0.022369081214190782 0.036467614070683996"/>
      <mass value="0.3817226974329336"/>
      <inertia ixx="0.000328" ixy="-2.4e-05" ixz="6.5e-05" iyy="0.00037" iyz="6.8e-05" izz="0.000146"/>
    </inertial>
    <visual>
      <origin rpy="0 0 0" xyz="-0.001925 -0.034477 -0.275184"/>
      <geometry>
        <mesh filename="./meshes/link3_1_1.stl" scale="0.001 0.001 0.001"/>
      </geometry>
      <material name="silver"/>
    </visual>
    <collision>
      <origin rpy="0 0 0" xyz="-0.001925 -0.034477 -0.275184"/>
      <geometry>
        <mesh filename="./meshes/link3_1_1.stl" scale="0.001 0.001 0.001"/>
      </geometry>
    </collision>
  </link>
  <link name="link4_1_1">
    <inertial>
      <origin rpy="0 0 0" xyz="-0.004221306676286125 0.09021372117053507 0.00026828289249919424"/>
      <mass value="0.44370009904209484"/>
      <inertia ixx="0.001103" ixy="-3.2e-05" ixz="1e-06" iyy="0.00012" iyz="-1e-06" izz="0.001078"/>
    </inertial>
    <visual>
      <origin rpy="0 0 0" xyz="0.016625 -0.024477 -0.327184"/>
      <geometry>
        <mesh filename="./meshes/link4_1_1.stl" scale="0.001 0.001 0.001"/>
      </geometry>
      <material name="silver"/>
    </visual>
    <collision>
      <origin rpy="0 0 0" xyz="0.016625 -0.024477 -0.327184"/>
      <geometry>
        <mesh filename="./meshes/link4_1_1.stl" scale="0.001 0.001 0.001"/>
      </geometry>
    </collision>
  </link>
  <link name="link5_1_1">
    <inertial>
      <origin rpy="0 0 0" xyz="-0.0007044959912857188 0.04181588666040692 1.9856549020258463e-05"/>
      <mass value="0.1329416987985629"/>
      <inertia ixx="0.000148" ixy="3e-05" ixz="0.0" iyy="3.5e-05" iyz="-0.0" izz="0.00016"/>
    </inertial>
    <visual>
      <origin rpy="0 0 0" xyz="-0.000175 -0.151477 -0.327184"/>
      <geometry>
        <mesh filename="./meshes/link5_1_1.stl" scale="0.001 0.001 0.001"/>
      </geometry>
      <material name="silver"/>
    </visual>
    <collision>
      <origin rpy="0 0 0" xyz="-0.000175 -0.151477 -0.327184"/>
      <geometry>
        <mesh filename="./meshes/link5_1_1.stl" scale="0.001 0.001 0.001"/>
      </geometry>
    </collision>
  </link>
  <link name="link6_1_1">
    <inertial>
      <origin rpy="0 0 0" xyz="8.866549679534264e-08 0.001500477150790519 2.701463612808652e-07"/>
      <mass value="0.00918018258883941"/>
      <inertia ixx="1e-06" ixy="0.0" ixz="-0.0" iyy="1e-06" iyz="0.0" izz="1e-06"/>
    </inertial>
    <visual>
      <origin rpy="0 0 0" xyz="0.018331 -0.228477 -0.327078"/>
      <geometry>
        <mesh filename="./meshes/link6_1_1.stl" scale="0.001 0.001 0.001"/>
      </geometry>
      <material name="silver"/>
    </visual>
    <collision>
      <origin rpy="0 0 0" xyz="0.018331 -0.228477 -0.327078"/>
      <geometry>
        <mesh filename="./meshes/link6_1_1.stl" scale="0.001 0.001 0.001"/>
      </geometry>
    </collision>
  </link>
  <link name="tool0">
    <inertial>
      <origin rpy="0 0 0" xyz="0 0 0.05"/> <!-- 假设重心位于矩形中间偏前 -->
      <mass value="0.05"/>
      <inertia ixx="1e-5" ixy="0.0" ixz="0.0" iyy="1e-5" iyz="0.0" izz="1e-5"/>
    </inertial>
    <visual>
      <origin rpy="0 0 0" xyz="0 0 0.05"/> <!-- 相机的几何中心 -->
      <geometry>
        <box size="0.08 0.04 0.04"/> <!-- 4x4x10 cm 的相机形状 -->
      </geometry>
      <material name="silver"/>
    </visual>
    <collision>
      <origin rpy="0 0 0" xyz="0 0 0.05"/>
      <geometry>
        <box size="0.04 0.04 0.1"/>
      </geometry>
    </collision>
  </link>
  <joint name="Joint1" type="revolute">
    <origin rpy="0 0 0" xyz="-0.019225 -0.000523 0.100684"/>
    <parent link="base_link"/>
    <child link="link1_1_1"/>
    <axis xyz="0.0 -0.0 -1.0"/>
    <limit effort="150" lower="-2.93" upper="2.18" velocity="3.15"/>
  </joint>
  <joint name="Joint2" type="revolute">
    <origin rpy="0 0 0" xyz="-0.0155 0.035 0.0285"/>
    <parent link="link1_1_1"/>
    <child link="link2_1_1"/>
    <axis xyz="-1.0 -0.0 0.0"/>
    <limit effort="150" lower="-1.27" upper="1.27" velocity="3.15"/>
  </joint>
  <joint name="Joint3" type="revolute">
    <origin rpy="0 0 0" xyz="0.03665 0.0 0.146"/>
    <parent link="link2_1_1"/>
    <child link="link3_1_1"/>
    <axis xyz="-1.0 0.0 -0.0"/>
    <limit effort="150" lower="0.68" upper="3.11" velocity="3.15"/>
  </joint>
  <joint name="Joint4" type="revolute">
    <origin rpy="0 0 0" xyz="-0.01855 -0.01 0.052"/>
    <parent link="link3_1_1"/>
    <child link="link4_1_1"/>
    <axis xyz="0.0 -1.0 0.0"/>
    <limit effort="150" lower="-3.11" upper="2.71" velocity="3.15"/>
  </joint>
  <joint name="Joint5" type="revolute">
    <origin rpy="0 0 0" xyz="0.0168 0.127 0.0"/>
    <parent link="link4_1_1"/>
    <child link="link5_1_1"/>
    <axis xyz="-1.0 0.0 -0.0"/>
    <limit effort="150" lower="-1.8" upper="1.8" velocity="3.15"/>
  </joint>
  <joint name="Joint6" type="revolute">
    <origin rpy="0 0 0" xyz="-0.018506 0.077 -0.000106"/>
    <parent link="link5_1_1"/>
    <child link="link6_1_1"/>
    <axis xyz="-0.0 -1.0 0.0"/>
    <limit effort="150" lower="-3.14" upper="3.14" velocity="3.15"/>
  </joint>
  <joint name="tool0_joint" type="fixed">
    <parent link="link6_1_1"/>
    <child link="tool0"/>
    <origin xyz="0 0.03 -0.05" rpy="0 0 0"/> <!-- 位于 link6_1_1 正前方 5 cm -->
  </joint>
</robot>
